Workbook

Sheet Sprint 1
A1: Project name: | C1: AgoraLearn+ Nền tảng học trực tuyến với AI Attendance, phân tích tương tác học tập và gợi ý cải thiện | F1: Kết thúc đúng hạn
A2: Module name: | C2: Sprint 1 | F2: Muộn
A3: Start date: | C3: 27/09/2025 | F3: Trước thời hạn
A4: End date: | C4: 45668
B6: SPRINT 2 REPORT
B7: No | C7: Thành viên | D7: Thực tế | E7: Ước tính
B8: 1 | C8: Nguyễn Văn Viên | D8: =SUMIF($E$14:$F$81,"Viên",$G$14:$G$81)+SUMIF($E$14:$F$81,"All team",$G$14:$G$81)/4+SUMIF($E$14:$F$81,"Hoàng, Viên",$G$14:$G$81)/2+SUMIF($E$14:$F$81,"Viên, Vinh",$G$14:$G$81)/2 -> 49.5 | E8: =SUMIF($E$14:$F$81,"Viên",$H$14:$H$81)+SUMIF($E$14:$F$81,"All team",$H$14:$H$81)/4+SUMIF($E$14:$F$81,"Hoàng, Viên",$H$14:$H$81)/2+SUMIF($E$14:$F$81,"Viên, Vinh",$H$14:$H$81)/2 -> 48
B9: 2 | C9: Lê Tuấn Trình | D9: =SUMIF($E$14:$F$81,"Trình",$G$14:$G$81)+SUMIF($E$14:$F$81,"All team",$G$14:$G$81)/4+SUMIF($E$14:$F$81,"Trình,Vinh",$G$14:$G$81)/2+SUMIF($E$14:$F$81,"Trình, Hoàng",$G$14:$G$81)/2 -> 35.5 | E9: =SUMIF($E$14:$F$81,"Trình",$H$14:$H$81)+SUMIF($E$14:$F$81,"All team",$H$14:$H$81)/4+SUMIF($E$14:$F$81,"Trình, Hoàng",$H$14:$H$81)/2+SUMIF($E$14:$F$81,"Trình,Vinh",$H$14:$H$81)/2 -> 37
B10: 3 | C10: Dương Quang Vinh | D10: =SUMIF($E$14:$F$81,"Vinh",$G$14:$G$81)+SUMIF($E$14:$F$81,"All team",$G$14:$G$81)/4+SUMIF($E$14:$F$81,"Vinh, Hoàng",$G$14:$G$81)/2+SUMIF($E$14:$F$81,"Trình, Vinh",$G$14:$G$81)/2+SUMIF($E$14:$F$81,"Viên, Vinh",$G$14:$G$81)/2 -> 31.5 | E10: =SUMIF($E$14:$F$81,"Vinh",$H$14:$H$81)+SUMIF($E$14:$F$81,"All team",$H$14:$H$81)/4+SUMIF($E$14:$F$81,"Vinh, Hoàng",$H$14:$H$81)/2+SUMIF($E$14:$F$81,"Trình, Vinh",$G$14:$G$81)/2+SUMIF($E$14:$F$81,"Viên, Vinh",$G$14:$G$81)/2 -> 30
B11: 4 | C11: Trần Dương Huy Hoàng | D11: =SUMIF($E$14:$F$81,"Hoàng",$G$14:$G$81)+SUMIF($E$14:$F$81,"All team",$G$14:$G$81)/4+SUMIF($E$14:$F$81,"Trình, Hoàng",$G$14:$G$81)/2+SUMIF($E$14:$F$81,"Hoàng, Viên",$G$14:$G$81)/2+SUMIF($E$14:$F$81,"Vinh, Hoàng",$G$14:$G$81)/2 -> 33.5 | E11: =SUMIF($E$14:$F$81,"Hoàng",$H$14:$H$81)+SUMIF($E$14:$F$81,"All team",$H$14:$H$81)/4+SUMIF($E$14:$F$81,"Trình, Hoàng",$H$14:$H$81)/2+SUMIF($E$14:$F$81,"Hoàng, Viên",$H$14:$H$81)/2+SUMIF($E$14:$F$81,"Vinh, Hoàng",$H$14:$H$81)/2 -> 34
B12: Tổng | D12: =SUM(D8:D11) -> 150 | E12: =SUM(E8:E11) -> 149
A14: Sprint | B14: Compoment | C14: Task name | E14: Responsible Member | G14: Thực tế | H14: Ước tính | I14: 45927 | J14: 45928 | K14: 45929 | L14: 45930 | M14: 45931 | N14: 45932 | O14: 45933 | P14: 45934 | Q14: 45935 | R14: 45936 | S14: 45937 | T14: 45938 | U14: 45939 | V14: 45940 | W14: 45941 | X14: 45942 | Y14: 45943 | Z14: 45944 | AA14: 45945 | AB14: 45946 | AC14: 45947 | AD14: 45948 | AE14: 45949 | AF14: 45950 | AG14: 45951 | AH14: 45952 | AI14: 45953 | AJ14: 45954 | AK14: 45955 | AL14: 45956 | AM14: 45957 | AN14: 45958 | AO14: 45959 | AP14: 45960 | AQ14: 45961 | AR14: 45962
A15: Sprint 1 | B15: Họp kế hoạch Sprint | E15: All team | G15: =H15-I15 -> 10 | H15: 10 | I15: 0 | J15: 0 | K15: 0 | L15: 0 | M15: 0 | N15: 0 | O15: 0 | P15: 0 | Q15: 0 | R15: 0 | S15: 0 | T15: 0 | U15: 0 | V15: 0 | W15: 0 | X15: 0 | Y15: 0 | Z15: 0 | AA15: 0 | AB15: 0 | AC15: 0 | AD15: 0 | AE15: 0 | AF15: 0 | AG15: 0 | AH15: 0 | AI15: 0 | AJ15: 0 | AK15: 0 | AL15: 0 | AM15: 0 | AN15: 0 | AO15: 0 | AP15: 0 | AQ15: 0 | AR15: 0
B16: Tạo Sprint Backlog 1 | E16: Vinh, Viên | G16: 4 | H16: 4 | I16: 4 | J16: 0 | K16: 0 | L16: 0 | M16: 0 | N16: 0 | O16: 0 | P16: 0 | Q16: 0 | R16: 0 | S16: 0 | T16: 0 | U16: 0 | V16: 0 | W16: 0 | X16: 0 | Y16: 0 | Z16: 0 | AA16: 0 | AB16: 0 | AC16: 0 | AD16: 0 | AE16: 0 | AF16: 0 | AG16: 0 | AH16: 0 | AI16: 0 | AJ16: 0 | AK16: 0 | AL16: 0 | AM16: 0 | AN16: 0 | AO16: 0 | AP16: 0 | AQ16: 0 | AR16: 0
B17: Tạo tài liệu kiểm thử cho Sprint | E17: Trình, Hoàng | G17: =H17-K17 -> 4 | H17: 4 | I17: 4 | J17: 0 | K17: 0 | L17: 0 | M17: 0 | N17: 0 | O17: 0 | P17: 0 | Q17: 0 | R17: 0 | S17: 0 | T17: 0 | U17: 0 | V17: 0 | W17: 0 | X17: 0 | Y17: 0 | Z17: 0 | AA17: 0 | AB17: 0 | AC17: 0 | AD17: 0 | AE17: 0 | AF17: 0 | AG17: 0 | AH17: 0 | AI17: 0 | AJ17: 0 | AK17: 0 | AL17: 0 | AM17: 0 | AN17: 0 | AO17: 0 | AP17: 0 | AQ17: 0 | AR17: 0
B18: User interface design | C18: Giao diện đăng nhập | E18: Vinh | G18: 1 | H18: 1 | I18: 1 | J18: 1 | K18: 0 | L18: 0 | M18: 0 | N18: 0 | O18: 0 | P18: 0 | Q18: 0 | R18: 0 | S18: 0 | T18: 0 | U18: 0 | V18: 0 | W18: 0 | X18: 0 | Y18: 0 | Z18: 0 | AA18: 0 | AB18: 0 | AC18: 0 | AD18: 0 | AE18: 0 | AF18: 0 | AG18: 0 | AH18: 0 | AI18: 0 | AJ18: 0 | AK18: 0 | AL18: 0 | AM18: 0 | AN18: 0 | AO18: 0 | AP18: 0 | AQ18: 0 | AR18: 0
C19: Giao diện đăng ký | E19: Vinh | G19: 1 | H19: 1 | I19: 1 | J19: 1 | K19: 0 | L19: 0 | M19: 0 | N19: 0 | O19: 0 | P19: 0 | Q19: 0 | R19: 0 | S19: 0 | T19: 0 | U19: 0 | V19: 0 | W19: 0 | X19: 0 | Y19: 0 | Z19: 0 | AA19: 0 | AB19: 0 | AC19: 0 | AD19: 0 | AE19: 0 | AF19: 0 | AG19: 0 | AH19: 0 | AI19: 0 | AJ19: 0 | AK19: 0 | AL19: 0 | AM19: 0 | AN19: 0 | AO19: 0 | AP19: 0 | AQ19: 0 | AR19: 0
C20: Giao diện đăng xuất | E20: Vinh | G20: 1 | H20: 1 | I20: 1 | J20: 1 | K20: 0 | L20: 0 | M20: 0 | N20: 0 | O20: 0 | P20: 0 | Q20: 0 | R20: 0 | S20: 0 | T20: 0 | U20: 0 | V20: 0 | W20: 0 | X20: 0 | Y20: 0 | Z20: 0 | AA20: 0 | AB20: 0 | AC20: 0 | AD20: 0 | AE20: 0 | AF20: 0 | AG20: 0 | AH20: 0 | AI20: 0 | AJ20: 0 | AK20: 0 | AL20: 0 | AM20: 0 | AN20: 0 | AO20: 0 | AP20: 0 | AQ20: 0 | AR20: 0
C21: Giao diện đổi mật khẩu | E21: Vinh | G21: 3 | H21: 1 | I21: 2 | J21: 2 | K21: 2 | L21: 0 | M21: 0 | N21: 0 | O21: 0 | P21: 0 | Q21: 0 | R21: 0 | S21: 0 | T21: 0 | U21: 0 | V21: 0 | W21: 0 | X21: 0 | Y21: 0 | Z21: 0 | AA21: 0 | AB21: 0 | AC21: 0 | AD21: 0 | AE21: 0 | AF21: 0 | AG21: 0 | AH21: 0 | AI21: 0 | AJ21: 0 | AK21: 0 | AL21: 0 | AM21: 0 | AN21: 0 | AO21: 0 | AP21: 0 | AQ21: 0 | AR21: 0
L22: 2
C23: Giao diện quản lý hồ sơ cá nhân | E23: Trình | G23: 2 | H23: 2 | I23: 1 | J23: 1 | K23: 0 | L23: 0 | M23: 0 | N23: 0 | O23: 0 | P23: 0 | Q23: 0 | R23: 0 | S23: 0 | T23: 0 | U23: 0 | V23: 0 | W23: 0 | X23: 0 | Y23: 0 | Z23: 0 | AA23: 0 | AB23: 0 | AC23: 0 | AD23: 0 | AE23: 0 | AF23: 0 | AG23: 0 | AH23: 0 | AI23: 0 | AJ23: 0 | AK23: 0 | AL23: 0 | AM23: 0 | AN23: 0 | AO23: 0 | AP23: 0 | AQ23: 0 | AR23: 0
C24: Giao diện phân quyền người dùng | E24: Trình | G24: 2 | H24: 2 | I24: 2 | J24: 1 | K24: 0 | L24: 1 | M24: 0 | N24: 0 | O24: 0 | P24: 0 | Q24: 0 | R24: 0 | S24: 0 | T24: 0 | U24: 0 | V24: 0 | W24: 0 | X24: 0 | Y24: 0 | Z24: 0 | AA24: 0 | AB24: 0 | AC24: 0 | AD24: 0 | AE24: 0 | AF24: 0 | AG24: 0 | AH24: 0 | AI24: 0 | AJ24: 0 | AK24: 0 | AL24: 0 | AM24: 0 | AN24: 0 | AO24: 0 | AP24: 0 | AQ24: 0 | AR24: 0
C25: Giao diện quản lý lớp học trực tuyến | E25: Viên | G25: 2 | H25: 2 | I25: 2 | J25: 1 | K25: 1 | L25: 0 | M25: 0 | N25: 0 | O25: 0 | P25: 0 | Q25: 0 | R25: 0 | S25: 0 | T25: 0 | U25: 0 | V25: 0 | W25: 0 | X25: 0 | Y25: 0 | Z25: 0 | AA25: 0 | AB25: 0 | AC25: 0 | AD25: 0 | AE25: 0 | AF25: 0 | AG25: 0 | AH25: 0 | AI25: 0 | AJ25: 0 | AK25: 0 | AL25: 0 | AM25: 0 | AN25: 0 | AO25: 0 | AP25: 0 | AQ25: 0 | AR25: 0
C26: Giao diện quản lý tài liệu học tập | E26: Viên | G26: 2 | H26: 2 | I26: 2 | J26: 2 | K26: 1 | L26: 0 | M26: 0 | N26: 0 | O26: 0 | P26: 0 | Q26: 0 | R26: 0 | S26: 0 | T26: 0 | U26: 0 | V26: 0 | W26: 0 | X26: 0 | Y26: 0 | Z26: 0 | AA26: 0 | AB26: 0 | AC26: 0 | AD26: 0 | AE26: 0 | AF26: 0 | AG26: 0 | AH26: 0 | AI26: 0 | AJ26: 0 | AK26: 0 | AL26: 0 | AM26: 0 | AN26: 0 | AO26: 0 | AP26: 0 | AQ26: 0 | AR26: 0
C27: Giao diện quản lý sinh viên | E27: Hoàng | G27: 2 | H27: 2 | I27: 2 | J27: 1 | K27: 1 | L27: 0 | M27: 0 | N27: 0 | O27: 0 | P27: 0 | Q27: 0 | R27: 0 | S27: 0 | T27: 0 | U27: 0 | V27: 0 | W27: 0 | X27: 0 | Y27: 0 | Z27: 0 | AA27: 0 | AB27: 0 | AC27: 0 | AD27: 0 | AE27: 0 | AF27: 0 | AG27: 0 | AH27: 0 | AI27: 0 | AJ27: 0 | AK27: 0 | AL27: 0 | AM27: 0 | AN27: 0 | AO27: 0 | AP27: 0 | AQ27: 0 | AR27: 0
C28: Giao diện quản lý bài tập và kết quả | E28: Hoàng | G28: 2 | H28: 2 | I28: 2 | J28: 1 | K28: 1 | L28: 0 | M28: 0 | N28: 0 | O28: 0 | P28: 0 | Q28: 0 | R28: 0 | S28: 0 | T28: 0 | U28: 0 | V28: 0 | W28: 0 | X28: 0 | Y28: 0 | Z28: 0 | AA28: 0 | AB28: 0 | AC28: 0 | AD28: 0 | AE28: 0 | AF28: 0 | AG28: 0 | AH28: 0 | AI28: 0 | AJ28: 0 | AK28: 0 | AL28: 0 | AM28: 0 | AN28: 0 | AO28: 0 | AP28: 0 | AQ28: 0 | AR28: 0
C29: Review all user interfaces of sprint 1 | E29: All team | G29: =H29+N30 -> 10 | H29: 10 | I29: 10 | J29: 10 | K29: 10 | L29: 9 | M29: 0 | N29: 0 | O29: 0 | P29: 0 | Q29: 0 | R29: 0 | S29: 0 | T29: 0 | U29: 0 | V29: 0 | W29: 0 | X29: 0 | Y29: 0 | Z29: 0 | AA29: 0 | AB29: 0 | AC29: 0 | AD29: 0 | AE29: 0 | AF29: 0 | AG29: 0 | AH29: 0 | AI29: 0 | AJ29: 0 | AK29: 0 | AL29: 0 | AM29: 0 | AN29: 0 | AO29: 0 | AP29: 0 | AQ29: 0 | AR29: 0
M30: -1
B31: Design test case | C31: Thiết kế trường kiểm thử cho đăng nhập | E31: Hoàng | G31: 1 | H31: 1 | I31: 1 | J31: 1 | K31: 1 | L31: 1 | M31: 1 | N31: 0 | O31: 0 | P31: 0 | Q31: 0 | R31: 0 | S31: 0 | T31: 0 | U31: 0 | V31: 0 | W31: 0 | X31: 0 | Y31: 0 | Z31: 0 | AA31: 0 | AB31: 0 | AC31: 0 | AD31: 0 | AE31: 0 | AF31: 0 | AG31: 0 | AH31: 0 | AI31: 0 | AJ31: 0 | AK31: 0 | AL31: 0 | AM31: 0 | AN31: 0 | AO31: 0 | AP31: 0 | AQ31: 0 | AR31: 0
C32: Thiết kế trường kiểm thử cho đăng ký | E32: Hoàng | G32: 1 | H32: 1 | I32: 1 | J32: 1 | K32: 1 | L32: 1 | M32: 1 | N32: 0 | O32: 0 | P32: 0 | Q32: 0 | R32: 0 | S32: 0 | T32: 0 | U32: 0 | V32: 0 | W32: 0 | X32: 0 | Y32: 0 | Z32: 0 | AA32: 0 | AB32: 0 | AC32: 0 | AD32: 0 | AE32: 0 | AF32: 0 | AG32: 0 | AH32: 0 | AI32: 0 | AJ32: 0 | AK32: 0 | AL32: 0 | AM32: 0 | AN32: 0 | AO32: 0 | AP32: 0 | AQ32: 0 | AR32: 0
C33: Thiết kế trường kiểm thử cho đăng xuất | E33: Hoàng | G33: 1 | H33: 1 | I33: 1 | J33: 1 | K33: 1 | L33: 1 | M33: 1 | N33: 0 | O33: 0 | P33: 0 | Q33: 0 | R33: 0 | S33: 0 | T33: 0 | U33: 0 | V33: 0 | W33: 0 | X33: 0 | Y33: 0 | Z33: 0 | AA33: 0 | AB33: 0 | AC33: 0 | AD33: 0 | AE33: 0 | AF33: 0 | AG33: 0 | AH33: 0 | AI33: 0 | AJ33: 0 | AK33: 0 | AL33: 0 | AM33: 0 | AN33: 0 | AO33: 0 | AP33: 0 | AQ33: 0 | AR33: 0
C34: Thiết kế trường kiểm thử cho đổi mật khẩu | E34: Hoàng | G34: 1 | H34: 1 | I34: 1 | J34: 1 | K34: 1 | L34: 1 | M34: 1 | N34: 0 | O34: 0 | P34: 0 | Q34: 0 | R34: 0 | S34: 0 | T34: 0 | U34: 0 | V34: 0 | W34: 0 | X34: 0 | Y34: 0 | Z34: 0 | AA34: 0 | AB34: 0 | AC34: 0 | AD34: 0 | AE34: 0 | AF34: 0 | AG34: 0 | AH34: 0 | AI34: 0 | AJ34: 0 | AK34: 0 | AL34: 0 | AM34: 0 | AN34: 0 | AO34: 0 | AP34: 0 | AQ34: 0 | AR34: 0
C35: Thiết kế trường kiểm thử cho quản lý hồ sơ cá nhân | E35: Viên | G35: 2 | H35: 2 | I35: 2 | J35: 2 | K35: 1 | L35: 1 | M35: 1 | N35: 0 | O35: 0 | P35: 0 | Q35: 0 | R35: 0 | S35: 0 | T35: 0 | U35: 0 | V35: 0 | W35: 0 | X35: 0 | Y35: 0 | Z35: 0 | AA35: 0 | AB35: 0 | AC35: 0 | AD35: 0 | AE35: 0 | AF35: 0 | AG35: 0 | AH35: 0 | AI35: 0 | AJ35: 0 | AK35: 0 | AL35: 0 | AM35: 0 | AN35: 0 | AO35: 0 | AP35: 0 | AQ35: 0 | AR35: 0
C36: Thiết kế trường kiểm thử cho quản lý điểm danh | E36: Viên | G36: 2 | H36: 2 | I36: 2 | J36: 2 | K36: 2 | L36: 1 | M36: 1 | N36: 0 | O36: 0 | P36: 0 | Q36: 0 | R36: 0 | S36: 0 | T36: 0 | U36: 0 | V36: 0 | W36: 0 | X36: 0 | Y36: 0 | Z36: 0 | AA36: 0 | AB36: 0 | AC36: 0 | AD36: 0 | AE36: 0 | AF36: 0 | AG36: 0 | AH36: 0 | AI36: 0 | AJ36: 0 | AK36: 0 | AL36: 0 | AM36: 0 | AN36: 0 | AO36: 0 | AP36: 0 | AQ36: 0 | AR36: 0
C37: Thiết kế trường kiểm thử cho quản lý lớp học trực tuyến | E37: Viên | G37: 2 | H37: 2 | I37: 2 | J37: 2 | K37: 1 | L37: 1 | M37: 1 | N37: 0 | O37: 0 | P37: 0 | Q37: 0 | R37: 0 | S37: 0 | T37: 0 | U37: 0 | V37: 0 | W37: 0 | X37: 0 | Y37: 0 | Z37: 0 | AA37: 0 | AB37: 0 | AC37: 0 | AD37: 0 | AE37: 0 | AF37: 0 | AG37: 0 | AH37: 0 | AI37: 0 | AJ37: 0 | AK37: 0 | AL37: 0 | AM37: 0 | AN37: 0 | AO37: 0 | AP37: 0 | AQ37: 0 | AR37: 0
C38: Thiết kế trường kiểm thử cho quản lý tài liệu học tập | E38: Viên | G38: 3 | H38: 2 | I38: 3 | J38: 2 | K38: 2 | L38: 2 | M38: 2 | N38: 1 | O38: 1 | P38: 0 | Q38: 0 | R38: 0 | S38: 0 | T38: 0 | U38: 0 | V38: 0 | W38: 0 | X38: 0 | Y38: 0 | Z38: 0 | AA38: 0 | AB38: 0 | AC38: 0 | AD38: 0 | AE38: 0 | AF38: 0 | AG38: 0 | AH38: 0 | AI38: 0 | AJ38: 0 | AK38: 0 | AL38: 0 | AM38: 0 | AN38: 0 | AO38: 0 | AP38: 0 | AQ38: 0 | AR38: 0
P39: 1
C40: Thiết kế trường kiểm thử cho quản lý sinh viên | E40: Viên | G40: 2 | H40: 2 | I40: 2 | J40: 2 | K40: 2 | L40: 1 | M40: 1 | N40: 1 | O40: 0 | P40: 0 | Q40: 0 | R40: 0 | S40: 0 | T40: 0 | U40: 0 | V40: 0 | W40: 0 | X40: 0 | Y40: 0 | Z40: 0 | AA40: 0 | AB40: 0 | AC40: 0 | AD40: 0 | AE40: 0 | AF40: 0 | AG40: 0 | AH40: 0 | AI40: 0 | AJ40: 0 | AK40: 0 | AL40: 0 | AM40: 0 | AN40: 0 | AO40: 0 | AP40: 0 | AQ40: 0 | AR40: 0
C41: Thiết kế trường kiểm thử cho quản lý bài tập và kết quả | E41: Viên | G41: 3 | H41: 2 | I41: 3 | J41: 3 | K41: 2 | L41: 2 | M41: 2 | N41: 1 | O41: 1 | P41: 0 | Q41: 0 | R41: 0 | S41: 0 | T41: 0 | U41: 0 | V41: 0 | W41: 0 | X41: 0 | Y41: 0 | Z41: 0 | AA41: 0 | AB41: 0 | AC41: 0 | AD41: 0 | AE41: 0 | AF41: 0 | AG41: 0 | AH41: 0 | AI41: 0 | AJ41: 0 | AK41: 0 | AL41: 0 | AM41: 0 | AN41: 0 | AO41: 0 | AP41: 0 | AQ41: 0 | AR41: 0
P42: 1
...

Sheet Sprint 2
A1: Project name: | C1: AgoraLearn+ Nền tảng học trực tuyến với AI Attendance, phân tích tương tác học tập và gợi ý cải thiện | F1: Kết thúc
A2: Module name: | C2: Sprint 2 | F2: Tăng ca
A3: Start date: | C3: 45699 | F3: Muộn
A4: End date: | C4: 46003 | F4: Chậm tiến độ
F5: Trước thời hạn
B6: SPRINT 2 REPORT
B7: No | C7: Thành viên | D7: Thực tế | E7: Ước tính
B8: 1 | C8: Nguyễn Văn Viên | D8: =SUMIF($E$15:$F$82,"Viên",$G$15:$G$82)+SUMIF($E$15:$F$82,"All team",$G$15:$G$82)/4+SUMIF($E$15:$F$82,"Hoàng, Viên",$G$15:$G$82)/2+SUMIF($E$15:$F$82,"Viên, Vinh",$G$15:$G$82)/2 -> 27.25 | E8: =SUMIF($E$15:$F$82,"Viên",$H$15:$H$82)+SUMIF($E$15:$F$82,"All team",$H$15:$H$82)/4+SUMIF($E$15:$F$82,"Hoàng, Viên",$H$15:$H$82)/2+SUMIF($E$15:$F$82,"Viên, Vinh",$H$15:$H$82)/2 -> 39.5
B9: 2 | C9: Lê Tuấn Trình | D9: =SUMIF($E$15:$F$82,"Trình",$G$15:$G$82)+SUMIF($E$15:$F$82,"All team",$G$15:$G$82)/4+SUMIF($E$15:$F$82,"Trình,Vinh",$G$15:$G$82)/2+SUMIF($E$15:$F$82,"Trình, Hoàng",$G$15:$G$82)/2 -> 25.25 | E9: =SUMIF($E$15:$F$82,"Trình",$H$15:$H$82)+SUMIF($E$15:$F$82,"All team",$H$15:$H$82)/4+SUMIF($E$15:$F$82,"Trình, Hoàng",$H$15:$H$82)/2+SUMIF($E$15:$F$82,"Trình,Vinh",$H$15:$H$82)/2 -> 31.5
B10: 3 | C10: Dương Quang Vinh | D10: =SUMIF($E$15:$F$82,"Vinh",$G$15:$G$82)+SUMIF($E$15:$F$82,"All team",$G$15:$G$82)/4+SUMIF($E$15:$F$82,"Vinh, Hoàng",$G$15:$G$82)/2+SUMIF($E$15:$F$82,"Trình, Vinh",$G$15:$G$82)/2+SUMIF($E$15:$F$82,"Viên, Vinh",$G$15:$G$82)/2 -> 19.25 | E10: =SUMIF($E$15:$F$82,"Vinh",$H$15:$H$82)+SUMIF($E$15:$F$82,"All team",$H$15:$H$82)/4+SUMIF($E$15:$F$82,"Vinh, Hoàng",$H$15:$H$82)/2+SUMIF($E$15:$F$82,"Trình, Vinh",$G$15:$G$82)/2+SUMIF($E$15:$F$82,"Viên, Vinh",$G$15:$G$82)/2 -> 21.5
B11: 4 | C11: Trần Dương Huy Hoàng | D11: =SUMIF($E$15:$F$82,"Hoàng",$G$15:$G$82)+SUMIF($E$15:$F$82,"All team",$G$15:$G$82)/4+SUMIF($E$15:$F$82,"Trình, Hoàng",$G$15:$G$82)/2+SUMIF($E$15:$F$82,"Hoàng, Viên",$G$15:$G$82)/2+SUMIF($E$15:$F$82,"Vinh, Hoàng",$G$15:$G$82)/2 -> 29.75 | E11: =SUMIF($E$15:$F$82,"Hoàng",$H$15:$H$82)+SUMIF($E$15:$F$82,"All team",$H$15:$H$82)/4+SUMIF($E$15:$F$82,"Trình, Hoàng",$H$15:$H$82)/2+SUMIF($E$15:$F$82,"Hoàng, Viên",$H$15:$H$82)/2+SUMIF($E$15:$F$82,"Vinh, Hoàng",$H$15:$H$82)/2 -> 33
B12: Tổng | D12: =SUM(D8:D11) -> 101.5 | E12: =SUM(E8:E11) -> 125.5
A14: Sprint | B14: Compoment | C14: Task name | E14: Responsible Member | G14: Thực tế | H14: Ước tính | I14: 45598 | J14: 45599 | K14: 45600 | L14: 45601 | M14: 45602 | N14: 45603 | O14: 45604 | P14: 45605 | Q14: 45606 | R14: 45607 | S14: 45608 | T14: 45609 | U14: 45610 | V14: 45611 | W14: 45612 | X14: 45613 | Y14: 45614 | Z14: 45615 | AA14: 45616 | AB14: 45617 | AC14: 45618 | AD14: 45619 | AE14: 45620 | AF14: 45621 | AG14: 45622 | AH14: 45623 | AI14: 45624 | AJ14: 45625 | AK14: 45626 | AL14: 45627 | AM14: 45628 | AN14: 45629 | AO14: 45630 | AP14: 45631 | AQ14: 45632 | AR14: 45633 | AS14: 45634 | AT14: 45635 | AU14: 45636 | AV14: 45637 | AW14: 45638
A15: Sprint 2 | B15: Họp kế hoạch Sprint 2 | E15: All team | G15: 10 | H15: 10 | I15: 0 | J15: 0 | K15: 0 | L15: 0 | M15: 0 | N15: 0 | O15: 0 | P15: 0 | Q15: 0 | R15: 0 | S15: 0 | T15: 0 | U15: 0 | V15: 0 | W15: 0 | X15: 0 | Y15: 0 | Z15: 0 | AA15: 0 | AB15: 0 | AC15: 0 | AD15: 0 | AE15: 0 | AF15: 0 | AG15: 0 | AH15: 0 | AI15: 0 | AJ15: 0 | AK15: 0 | AL15: 0 | AM15: 0 | AN15: 0 | AO15: 0 | AP15: 0 | AQ15: 0 | AR15: 0 | AS15: 0 | AT15: 0 | AU15: 0 | AV15: 0 | AW15: 0
B16: Tạo Sprint Backlog 2 | E16: Hoàng, Viên | G16: 2 | H16: 4 | I16: 2 | J16: 2 | K16: 0 | L16: 0 | M16: 0 | N16: 0 | O16: 0 | P16: 0 | Q16: 0 | R16: 0 | S16: 0 | T16: 0 | U16: 0 | V16: 0 | W16: 0 | X16: 0 | Y16: 0 | Z16: 0 | AA16: 0 | AB16: 0 | AC16: 0 | AD16: 0 | AE16: 0 | AF16: 0 | AG16: 0 | AH16: 0 | AI16: 0 | AJ16: 0 | AK16: 0 | AL16: 0 | AM16: 0 | AN16: 0 | AO16: 0 | AP16: 0 | AQ16: 0 | AR16: 0 | AS16: 0 | AT16: 0 | AU16: 0 | AV16: 0 | AW16: 0
K17: 2 | Z17: 0 | AA17: 0 | AB17: 0 | AC17: 0 | AD17: 0 | AE17: 0 | AF17: 0 | AG17: 0 | AH17: 0 | AI17: 0 | AJ17: 0 | AK17: 0 | AL17: 0 | AM17: 0 | AN17: 0 | AO17: 0 | AP17: 0 | AQ17: 0 | AR17: 0 | AS17: 0 | AT17: 0 | AU17: 0 | AV17: 0 | AW17: 0
B18: Tạo tài liệu kiểm thử cho Sprint 2 | E18: Viên, Vinh | G18: 4 | H18: 4 | I18: 4 | J18: 4 | K18: 0 | L18: 0 | M18: 0 | N18: 0 | O18: 0 | P18: 0 | Q18: 0 | R18: 0 | S18: 0 | T18: 0 | U18: 0 | V18: 0 | W18: 0 | X18: 0 | Y18: 0 | Z18: 0 | AA18: 0 | AB18: 0 | AC18: 0 | AD18: 0 | AE18: 0 | AF18: 0 | AG18: 0 | AH18: 0 | AI18: 0 | AJ18: 0 | AK18: 0 | AL18: 0 | AM18: 0 | AN18: 0 | AO18: 0 | AP18: 0 | AQ18: 0 | AR18: 0 | AS18: 0 | AT18: 0 | AU18: 0 | AV18: 0 | AW18: 0
B19: User interface design | C19: Xem lớp học | E19: Viên | G19: 2 | H19: 4 | I19: 2 | J19: 2 | K19: 2 | L19: 0 | M19: 0 | N19: 0 | O19: 0 | P19: 0 | Q19: 0 | R19: 0 | S19: 0 | T19: 0 | U19: 0 | V19: 0 | W19: 0 | X19: 0 | Y19: 0 | Z19: 0 | AA19: 0 | AB19: 0 | AC19: 0 | AD19: 0 | AE19: 0 | AF19: 0 | AG19: 0 | AH19: 0 | AI19: 0 | AJ19: 0 | AK19: 0 | AL19: 0 | AM19: 0 | AN19: 0 | AO19: 0 | AP19: 0 | AQ19: 0 | AR19: 0 | AS19: 0 | AT19: 0 | AU19: 0 | AV19: 0 | AW19: 0
C20: Quản lí sự kiện | E20: Trình | G20: 1 | H20: 1 | I20: 1 | J20: 1 | K20: 1 | L20: 1 | M20: 0 | N20: 0 | O20: 0 | P20: 0 | Q20: 0 | R20: 0 | S20: 0 | T20: 0 | U20: 0 | V20: 0 | W20: 0 | X20: 0 | Y20: 0 | Z20: 0 | AA20: 0 | AB20: 0 | AC20: 0 | AD20: 0 | AE20: 0 | AF20: 0 | AG20: 0 | AH20: 0 | AI20: 0 | AJ20: 0 | AK20: 0 | AL20: 0 | AM20: 0 | AN20: 0 | AO20: 0 | AP20: 0 | AQ20: 0 | AR20: 0 | AS20: 0 | AT20: 0 | AU20: 0 | AV20: 0 | AW20: 0
C21: Quản lý khóa học | E21: Vinh | G21: 1 | H21: 1 | I21: 1 | J21: 1 | K21: 1 | L21: 1 | M21: 0 | N21: 0 | O21: 0 | P21: 0 | Q21: 0 | R21: 0 | S21: 0 | T21: 0 | U21: 0 | V21: 0 | W21: 0 | X21: 0 | Y21: 0 | Z21: 0 | AA21: 0 | AB21: 0 | AC21: 0 | AD21: 0 | AE21: 0 | AF21: 0 | AG21: 0 | AH21: 0 | AI21: 0 | AJ21: 0 | AK21: 0 | AL21: 0 | AM21: 0 | AN21: 0 | AO21: 0 | AP21: 0 | AQ21: 0 | AR21: 0 | AS21: 0 | AT21: 0 | AU21: 0 | AV21: 0 | AW21: 0
C22: Quản lý giảng viên | E22: Vinh | G22: 2 | H22: 2 | I22: 2 | J22: 2 | K22: 2 | L22: 2 | M22: 2 | N22: 0 | O22: 0 | P22: 0 | Q22: 0 | R22: 0 | S22: 0 | T22: 0 | U22: 0 | V22: 0 | W22: 0 | X22: 0 | Y22: 0 | Z22: 0 | AA22: 0 | AB22: 0 | AC22: 0 | AD22: 0 | AE22: 0 | AF22: 0 | AG22: 0 | AH22: 0 | AI22: 0 | AJ22: 0 | AK22: 0 | AL22: 0 | AM22: 0 | AN22: 0 | AO22: 0 | AP22: 0 | AQ22: 0 | AR22: 0 | AS22: 0 | AT22: 0 | AU22: 0 | AV22: 0 | AW22: 0
C23: Quản lý báo cáo và thống kê | E23: Trình | G23: 1 | H23: 1 | I23: 1 | J23: 1 | K23: 1 | L23: 1 | M23: 1 | N23: 1 | O23: 0 | P23: 0 | Q23: 0 | R23: 0 | S23: 0 | T23: 0 | U23: 0 | V23: 0 | W23: 0 | X23: 0 | Y23: 0 | Z23: 0 | AA23: 0 | AB23: 0 | AC23: 0 | AD23: 0 | AE23: 0 | AF23: 0 | AG23: 0 | AH23: 0 | AI23: 0 | AJ23: 0 | AK23: 0 | AL23: 0 | AM23: 0 | AN23: 0 | AO23: 0 | AP23: 0 | AQ23: 0 | AR23: 0 | AS23: 0 | AT23: 0 | AU23: 0 | AV23: 0 | AW23: 0
C24: Quản lí điểm | E24: Hoàng | G24: 1 | H24: 1 | I24: 2 | J24: 2 | K24: 2 | L24: 2 | M24: 2 | N24: 2 | O24: 0 | P24: 0 | Q24: 0 | R24: 0 | S24: 0 | T24: 0 | U24: 0 | V24: 0 | W24: 0 | X24: 0 | Y24: 0 | Z24: 0 | AA24: 0 | AB24: 0 | AC24: 0 | AD24: 0 | AE24: 0 | AF24: 0 | AG24: 0 | AH24: 0 | AI24: 0 | AJ24: 0 | AK24: 0 | AL24: 0 | AM24: 0 | AN24: 0 | AO24: 0 | AP24: 0 | AQ24: 0 | AR24: 0 | AS24: 0 | AT24: 0 | AU24: 0 | AV24: 0 | AW24: 0
C25: Quản lý phân quyền | E25: Hoàng | G25: 1 | H25: 1 | I25: 2 | J25: 2 | K25: 2 | L25: 2 | M25: 2 | N25: 2 | O25: 2 | P25: 0 | Q25: 0 | R25: 0 | S25: 0 | T25: 0 | U25: 0 | V25: 0 | W25: 0 | X25: 0 | Y25: 0 | Z25: 0 | AA25: 0 | AB25: 0 | AC25: 0 | AD25: 0 | AE25: 0 | AF25: 0 | AG25: 0 | AH25: 0 | AI25: 0 | AJ25: 0 | AK25: 0 | AL25: 0 | AM25: 0 | AN25: 0 | AO25: 0 | AP25: 0 | AQ25: 0 | AR25: 0 | AS25: 0 | AT25: 0 | AU25: 0 | AV25: 0 | AW25: 0
C26: Review all user interfaces of sprint 2 | E26: All team | G26: 5 | H26: 10 | I26: 5 | J26: 5 | K26: 5 | L26: 5 | M26: 5 | N26: 5 | O26: 5 | P26: 5 | Q26: 5 | R26: 0 | S26: 0 | T26: 0 | U26: 0 | V26: 0 | W26: 0 | X26: 0 | Y26: 0 | Z26: 0 | AA26: 0 | AB26: 0 | AC26: 0 | AD26: 0 | AE26: 0 | AF26: 0 | AG26: 0 | AH26: 0 | AI26: 0 | AJ26: 0 | AK26: 0 | AL26: 0 | AM26: 0 | AN26: 0 | AO26: 0 | AP26: 0 | AQ26: 0 | AR26: 0 | AS26: 0 | AT26: 0 | AU26: 0 | AV26: 0 | AW26: 0
K27: 0 | R27: 5 | Z27: 0 | AA27: 0 | AB27: 0 | AC27: 0 | AD27: 0 | AE27: 0 | AF27: 0 | AG27: 0 | AH27: 0 | AI27: 0 | AJ27: 0 | AK27: 0 | AL27: 0 | AM27: 0 | AN27: 0 | AO27: 0 | AP27: 0 | AQ27: 0 | AR27: 0 | AS27: 0 | AT27: 0 | AU27: 0 | AV27: 0 | AW27: 0
B28: Design test case | C28: Thiết kế trường kiểm thử cho xem lớp học | E28: Hoàng | G28: 2 | H28: 3 | I28: 2 | J28: 2 | K28: 2 | L28: 2 | M28: 2 | N28: 2 | O28: 2 | P28: 2 | Q28: 2 | R28: 2 | S28: 0 | T28: 0 | U28: 0 | V28: 0 | W28: 0 | X28: 0 | Y28: 0 | Z28: 0 | AA28: 0 | AB28: 0 | AC28: 0 | AD28: 0 | AE28: 0 | AF28: 0 | AG28: 0 | AH28: 0 | AI28: 0 | AJ28: 0 | AK28: 0 | AL28: 0 | AM28: 0 | AN28: 0 | AO28: 0 | AP28: 0 | AQ28: 0 | AR28: 0 | AS28: 0 | AT28: 0 | AU28: 0 | AV28: 0 | AW28: 0
S29: 1 | Z29: 0 | AA29: 0 | AB29: 0 | AC29: 0 | AD29: 0 | AE29: 0 | AF29: 0 | AG29: 0 | AH29: 0 | AI29: 0 | AJ29: 0 | AK29: 0 | AL29: 0 | AM29: 0 | AN29: 0 | AO29: 0 | AP29: 0 | AQ29: 0 | AR29: 0 | AS29: 0 | AT29: 0 | AU29: 0 | AV29: 0 | AW29: 0
C30: Thiết kế trường kiểm thử cho Quản lí sự kiện | E30: Hoàng | G30: 1 | H30: 2 | I30: 1 | J30: 1 | K30: 1 | L30: 1 | M30: 1 | N30: 1 | O30: 1 | P30: 1 | Q30: 1 | R30: 1 | S30: 0 | T30: 0 | U30: 0 | V30: 0 | W30: 0 | X30: 0 | Y30: 0 | Z30: 0 | AA30: 0 | AB30: 0 | AC30: 0 | AD30: 0 | AE30: 0 | AF30: 0 | AG30: 0 | AH30: 0 | AI30: 0 | AJ30: 0 | AK30: 0 | AL30: 0 | AM30: 0 | AN30: 0 | AO30: 0 | AP30: 0 | AQ30: 0 | AR30: 0 | AS30: 0 | AT30: 0 | AU30: 0 | AV30: 0 | AW30: 0
S31: 1 | Z31: 0 | AA31: 0 | AB31: 0 | AC31: 0 | AD31: 0 | AE31: 0 | AF31: 0 | AG31: 0 | AH31: 0 | AI31: 0 | AJ31: 0 | AK31: 0 | AL31: 0 | AM31: 0 | AN31: 0 | AO31: 0 | AP31: 0 | AQ31: 0 | AR31: 0 | AS31: 0 | AT31: 0 | AU31: 0 | AV31: 0 | AW31: 0
C32: Thiết kế trường kiểm thử cho Quản lý khóa học | E32: Trình | G32: 1 | H32: 2 | I32: 1 | J32: 1 | K32: 1 | L32: 1 | M32: 1 | N32: 1 | O32: 1 | P32: 1 | Q32: 1 | R32: 1 | S32: 0 | T32: 0 | U32: 0 | V32: 0 | W32: 0 | X32: 0 | Y32: 0 | Z32: 0 | AA32: 0 | AB32: 0 | AC32: 0 | AD32: 0 | AE32: 0 | AF32: 0 | AG32: 0 | AH32: 0 | AI32: 0 | AJ32: 0 | AK32: 0 | AL32: 0 | AM32: 0 | AN32: 0 | AO32: 0 | AP32: 0 | AQ32: 0 | AR32: 0 | AS32: 0 | AT32: 0 | AU32: 0 | AV32: 0 | AW32: 0
S33: 1 | Z33: 0 | AA33: 0 | AB33: 0 | AC33: 0 | AD33: 0 | AE33: 0 | AF33: 0 | AG33: 0 | AH33: 0 | AI33: 0 | AJ33: 0 | AK33: 0 | AL33: 0 | AM33: 0 | AN33: 0 | AO33: 0 | AP33: 0 | AQ33: 0 | AR33: 0 | AS33: 0 | AT33: 0 | AU33: 0 | AV33: 0 | AW33: 0
C34: Thiết kế trường kiểm thử cho Quản lý giảng viên | E34: Trình | G34: 1 | H34: 2 | I34: 1 | J34: 1 | K34: 1 | L34: 1 | M34: 1 | N34: 1 | O34: 1 | P34: 1 | Q34: 1 | R34: 1 | S34: 0 | T34: 0 | U34: 0 | V34: 0 | W34: 0 | X34: 0 | Y34: 0 | Z34: 0 | AA34: 0 | AB34: 0 | AC34: 0 | AD34: 0 | AE34: 0 | AF34: 0 | AG34: 0 | AH34: 0 | AI34: 0 | AJ34: 0 | AK34: 0 | AL34: 0 | AM34: 0 | AN34: 0 | AO34: 0 | AP34: 0 | AQ34: 0 | AR34: 0 | AS34: 0 | AT34: 0 | AU34: 0 | AV34: 0 | AW34: 0
S35: 1 | Z35: 0 | AA35: 0 | AB35: 0 | AC35: 0 | AD35: 0 | AE35: 0 | AF35: 0 | AG35: 0 | AH35: 0 | AI35: 0 | AJ35: 0 | AK35: 0 | AL35: 0 | AM35: 0 | AN35: 0 | AO35: 0 | AP35: 0 | AQ35: 0 | AR35: 0 | AS35: 0 | AT35: 0 | AU35: 0 | AV35: 0 | AW35: 0
C36: Thiết kế trường kiểm thử cho Quản lý báo cáo và thống kê | E36: Viên | G36: 1 | H36: 2 | I36: 1 | J36: 1 | K36: 1 | L36: 1 | M36: 1 | N36: 1 | O36: 1 | P36: 1 | Q36: 1 | R36: 1 | S36: 1 | T36: 0 | U36: 0 | V36: 0 | W36: 0 | X36: 0 | Y36: 0 | Z36: 0 | AA36: 0 | AB36: 0 | AC36: 0 | AD36: 0 | AE36: 0 | AF36: 0 | AG36: 0 | AH36: 0 | AI36: 0 | AJ36: 0 | AK36: 0 | AL36: 0 | AM36: 0 | AN36: 0 | AO36: 0 | AP36: 0 | AQ36: 0 | AR36: 0 | AS36: 0 | AT36: 0 | AU36: 0 | AV36: 0 | AW36: 0
T37: 1 | Z37: 0 | AA37: 0 | AB37: 0 | AC37: 0 | AD37: 0 | AE37: 0 | AF37: 0 | AG37: 0 | AH37: 0 | AI37: 0 | AJ37: 0 | AK37: 0 | AL37: 0 | AM37: 0 | AN37: 0 | AO37: 0 | AP37: 0 | AQ37: 0 | AR37: 0 | AS37: 0 | AT37: 0 | AU37: 0 | AV37: 0 | AW37: 0
C38: Thiết kế trường kiểm thử cho Quản lí điểm | E38: Viên | G38: 1 | H38: 2 | I38: 1 | J38: 1 | K38: 1 | L38: 1 | M38: 1 | N38: 1 | O38: 1 | P38: 1 | Q38: 1 | R38: 1 | S38: 1 | T38: 0 | U38: 0 | V38: 0 | W38: 0 | X38: 0 | Y38: 0 | Z38: 0 | AA38: 0 | AB38: 0 | AC38: 0 | AD38: 0 | AE38: 0 | AF38: 0 | AG38: 0 | AH38: 0 | AI38: 0 | AJ38: 0 | AK38: 0 | AL38: 0 | AM38: 0 | AN38: 0 | AO38: 0 | AP38: 0 | AQ38: 0 | AR38: 0 | AS38: 0 | AT38: 0 | AU38: 0 | AV38: 0 | AW38: 0
T39: 1 | Z39: 0 | AA39: 0 | AB39: 0 | AC39: 0 | AD39: 0 | AE39: 0 | AF39: 0 | AG39: 0 | AH39: 0 | AI39: 0 | AJ39: 0 | AK39: 0 | AL39: 0 | AM39: 0 | AN39: 0 | AO39: 0 | AP39: 0 | AQ39: 0 | AR39: 0 | AS39: 0 | AT39: 0 | AU39: 0 | AV39: 0 | AW39: 0
C40: Thiết kế trường kiểm thử cho Quản lý phân quyền | E40: Viên | G40: 1 | H40: 2 | I40: 1 | J40: 1 | K40: 1 | L40: 1 | M40: 1 | N40: 1 | O40: 1 | P40: 1 | Q40: 1 | R40: 1 | S40: 1 | T40: 0 | U40: 0 | V40: 0 | W40: 0 | X40: 0 | Y40: 0 | Z40: 0 | AA40: 0 | AB40: 0 | AC40: 0 | AD40: 0 | AE40: 0 | AF40: 0 | AG40: 0 | AH40: 0 | AI40: 0 | AJ40: 0 | AK40: 0 | AL40: 0 | AM40: 0 | AN40: 0 | AO40: 0 | AP40: 0 | AQ40: 0 | AR40: 0 | AS40: 0 | AT40: 0 | AU40: 0 | AV40: 0 | AW40: 0
T41: 1 | Z41: 0 | AA41: 0 | AB41: 0 | AC41: 0 | AD41: 0 | AE41: 0 | AF41: 0 | AG41: 0 | AH41: 0 | AI41: 0 | AJ41: 0 | AK41: 0 | AL41: 0 | AM41: 0 | AN41: 0 | AO41: 0 | AP41: 0 | AQ41: 0 | AR41: 0 | AS41: 0 | AT41: 0 | AU41: 0 | AV41: 0 | AW41: 0
...

Sheet Total
A1: SPRINT BACKLOG REPORT
B2: Viên | D2: Trình | F2: Hoàng | H2: Vinh
B3: Thực tế | C3: Ước tính | D3: Thực tế | E3: Ước tính | F3: Thực tế | G3: Ước tính | H3: Thực tế | I3: Ước tính
A4: Sprint 1 | B4: ='Sprint 1'!D8 -> 49.5 | C4: ='Sprint 1'!$E$8 -> 48 | D4: ='Sprint 1'!$D$9 -> 35.5 | E4: ='Sprint 1'!$E$9 -> 37 | F4: ='Sprint 1'!D11 -> 33.5 | G4: ='Sprint 1'!E11 -> 34 | H4: ='Sprint 1'!$D$10 -> 31.5 | I4: ='Sprint 1'!$E$10 -> 30
A5: Sprint 2 | B5: ='Sprint 2'!$D$8 -> 27.25 | C5: ='Sprint 2'!$E$8 -> 39.5 | D5: ='Sprint 2'!$D$9 -> 25.25 | E5: ='Sprint 2'!$E$9 -> 31.5 | F5: ='Sprint 2'!D11 -> 29.75 | G5: ='Sprint 2'!E11 -> 33 | H5: ='Sprint 2'!$D$10 -> 19.25 | I5: ='Sprint 2'!$E$10 -> 21.5
A6: Tổng | B6: =SUM(B4:B5) -> 76.75 | C6: =SUM(C4:C5) -> 87.5 | D6: =SUM(D4:D5) -> 60.75 | E6: =SUM(E4:E5) -> 68.5 | F6: =SUM(F4:F5) -> 63.25 | G6: =SUM(G4:G5) -> 67 | H6: =SUM(H4:H5) -> 50.75 | I6: =SUM(I4:I5) -> 51.5
E9: FINAL TOTAL
E10: Thực tế | F10: =SUMIF($B$3:$I$3,"Thực tế",$B$6:$I$6) -> 251.5
E11: Ước tính | F11: =SUMIF($B$3:$I$3,"Ước tính",$B$6:$I$6) -> 274.5
